Workbook

Sheet Read Me
B2: Farm De Rai — Rent-to-Buy Model
B3: How to use this workbook
B6: This is a standalone ALTERNATIVE to the horse sanctuary / land-purchase plan — a different business
B7: (farm-stay + EV charging + restaurant) on the same 42 rai, leased first and purchased at Year 5.
B8: Change any blue number and every sheet, including the Summary chart, recalculates.
B10: Color legend
B11: Blue text = an input you can change
B12: Black text = a formula
B13: Green text = a link pulling a value from another sheet
B14: Pale yellow fill = a key assumption worth double-checking before you rely on this model
B16: Sheet guide
B17: Assumptions — land rent, occupancy/utilization ramps, pricing, staffing, and the Year-5 buy/sell terms
... B24: real construction/procurement quotes, and grid capacity for the fast chargers before relying on this.

Sheet Assumptions
B2: Assumptions
B3: Every input the model uses — change values here (blue cells)
B5: LAND — LEASE (not purchased upfront)
B6: Total land (rai) | C6: 42
B7: Rent per rai per year (THB) | C7: 4000 | H7: Confirm this is ANNUAL, not monthly
B8: Lease start date | C8: 46296
B10: FARM-STAY (20 pre-built units)
B11: Units (count) | C11: 20
B12: Nightly rate (THB) | C12: 2800
B13: Assumption | C13: Year 1 | D13: Year 2 | E13: Year 3 | F13: Year 4 | G13: Year 5 | H13: Notes
B14: Occupancy % | C14: 0.3 | D14: 0.45 | E14: 0.55 | F14: 0.6 | G14: 0.62
B16: EV PARK & STAY (10 bays)
B17: Bays (count) | C17: 10
B18: Nightly rate (THB) | C18: 900
B19: Assumption | C19: Year 1 | D19: Year 2 | E19: Year 3 | F19: Year 4 | G19: Year 5 | H19: Notes
B20: Occupancy % | C20: 0.2 | D20: 0.35 | E20: 0.45 | F20: 0.5 | G20: 0.52
B22: FAST CHARGING (5 chargers)
B23: Chargers (count) | C23: 5
B24: kWh delivered per session | C24: 35
B25: Retail price (THB/kWh) | C25: 8
B26: Wholesale cost (THB/kWh) | C26: 5
B27: Assumption | C27: Year 1 | D27: Year 2 | E27: Year 3 | F27: Year 4 | G27: Year 5 | H27: Notes
B28: Sessions per charger per day | C28: 4 | D28: 7 | E28: 10 | F28: 11 | G28: 12
B30: RESTAURANT
B31: Average spend per cover (THB) | C31: 350
B32: Food & beverage cost (% of restaurant revenue) | C32: 0.32
B33: Assumption | C33: Year 1 | D33: Year 2 | E33: Year 3 | F33: Year 4 | G33: Year 5 | H33: Notes
B34: Covers per day | C34: 60 | D34: 100 | E34: 140 | F34: 150 | G34: 155
B36: OPERATING COSTS (per year)
B37: Assumption | C37: Year 1 | D37: Year 2 | E37: Year 3 | F37: Year 4 | G37: Year 5 | H37: Notes
B38: Staff | C38: 2232000 | D38: 2800000 | E38: 3200000 | F38: 3400000 | G38: 3500000
B39: Utilities | C39: 800000 | D39: 950000 | E39: 1100000 | F39: 1150000 | G39: 1200000
B40: Marketing | C40: 600000 | D40: 500000 | E40: 500000 | F40: 500000 | G40: 500000
B41: Admin | C41: 400000 | D41: 450000 | E41: 500000 | F41: 520000 | G41: 540000
B42: Maintenance | C42: 500000 | D42: 600000 | E42: 700000 | F42: 750000 | G42: 800000
B44: CAPEX (one-time)
B45: 20 pre-built farm-stay units (THB/unit) | C45: 500000
B46: Site infrastructure (roads, water, electrical backbone) | C46: 8000000
B47: EV park-and-stay pad (THB/pad) | C47: 200000
B48: DC fast charger, incl. install (THB/charger) | C48: 1200000
...

Sheet Capex
B2: Capital Expenditure
B3: ~฿ 38.0M upfront — no land purchase in this phase
B5: Item | C5: Amount (THB) | D5: % of total
B6: 20 pre-built farm-stay units | C6: =Assumptions!$C$45*Assumptions!$C$11 -> 10000000 | D6: =C6/$C$15 -> 0.26315789
B7: Site infrastructure (roads, water, electrical backbone) | C7: =Assumptions!$C$46 -> 8000000 | D7: =C7/$C$15 -> 0.21052632
B8: 10 EV park-and-stay pads | C8: =Assumptions!$C$47*Assumptions!$C$17 -> 2000000 | D8: =C8/$C$15 -> 0.052631579
B9: 5 DC fast chargers (incl. install) | C9: =Assumptions!$C$48*Assumptions!$C$23 -> 6000000 | D9: =C9/$C$15 -> 0.15789474
B10: Restaurant building + kitchen + furnishing | C10: =Assumptions!$C$49 -> 5000000 | D10: =C10/$C$15 -> 0.13157895
B11: Reception/admin building | C11: =Assumptions!$C$50 -> 2000000 | D11: =C11/$C$15 -> 0.052631579
B12: Equipment & vehicles | C12: =Assumptions!$C$51 -> 1500000 | D12: =C12/$C$15 -> 0.039473684
B13: Working capital reserve | C13: =Assumptions!$C$52 -> 1500000 | D13: =C13/$C$15 -> 0.039473684
B14: Contingency + legal/permits/lease deposit | C14: =Assumptions!$C$53 -> 2000000 | D14: =C14/$C$15 -> 0.052631579
B15: TOTAL CAPEX | C15: =SUM(C6:C14) -> 38000000 | D15: 1

Sheet Operating P&L
B2: 5-Year Operating Plan
B3: Farm-stay + EV park & charging + restaurant, on leased land
B5: Assumption | C5: Year 1 | D5: Year 2 | E5: Year 3 | F5: Year 4 | G5: Year 5 | H5: Notes
B6: REVENUE
B7: Farm-stay (units × occ × rate × 365) | C7: =Assumptions!$C$11*Assumptions!$C$14*Assumptions!$C$12*365 -> 6132000 | D7: =Assumptions!$C$11*Assumptions!$D$14*Assumptions!$C$12*365 -> 9198000 | E7: =Assumptions!$C$11*Assumptions!$E$14*Assumptions!$C$12*365 -> 11242000 | F7: =Assumptions!$C$11*Assumptions!$F$14*Assumptions!$C$12*365 -> 12264000 | G7: =Assumptions!$C$11*Assumptions!$G$14*Assumptions!$C$12*365 -> 12672800
B8: EV park & stay (bays × occ × rate × 365) | C8: =Assumptions!$C$17*Assumptions!$C$20*Assumptions!$C$18*365 -> 657000 | D8: =Assumptions!$C$17*Assumptions!$D$20*Assumptions!$C$18*365 -> 1149750 | E8: =Assumptions!$C$17*Assumptions!$E$20*Assumptions!$C$18*365 -> 1478250 | F8: =Assumptions!$C$17*Assumptions!$F$20*Assumptions!$C$18*365 -> 1642500 | G8: =Assumptions!$C$17*Assumptions!$G$20*Assumptions!$C$18*365 -> 1708200
B9: Fast charging (chargers × sessions/day × kWh × price × 365) | C9: =Assumptions!$C$23*Assumptions!$C$28*Assumptions!$C$24*Assumptions!$C$25*365 -> 2044000 | D9: =Assumptions!$C$23*Assumptions!$D$28*Assumptions!$C$24*Assumptions!$C$25*365 -> 3577000 | E9: =Assumptions!$C$23*Assumptions!$E$28*Assumptions!$C$24*Assumptions!$C$25*365 -> 5110000 | F9: =Assumptions!$C$23*Assumptions!$F$28*Assumptions!$C$24*Assumptions!$C$25*365 -> 5621000 | G9: =Assumptions!$C$23*Assumptions!$G$28*Assumptions!$C$24*Assumptions!$C$25*365 -> 6132000
B10: Restaurant (covers/day × avg spend × 365) | C10: =Assumptions!$C$34*Assumptions!$C$31*365 -> 7665000 | D10: =Assumptions!$D$34*Assumptions!$C$31*365 -> 12775000 | E10: =Assumptions!$E$34*Assumptions!$C$31*365 -> 17885000 | F10: =Assumptions!$F$34*Assumptions!$C$31*365 -> 19162500 | G10: =Assumptions!$G$34*Assumptions!$C$31*365 -> 19801250
B11: TOTAL REVENUE | C11: =SUM(C7:C10) -> 16498000 | D11: =SUM(D7:D10) -> 26699750 | E11: =SUM(E7:E10) -> 35715250 | F11: =SUM(F7:F10) -> 38690000 | G11: =SUM(G7:G10) -> 40314250
B13: OPERATING COST
B14: Land rent (42 rai × ฿/rai/yr) | C14: =Assumptions!$C$6*Assumptions!$C$7 -> 168000 | D14: =Assumptions!$C$6*Assumptions!$C$7 -> 168000 | E14: =Assumptions!$C$6*Assumptions!$C$7 -> 168000 | F14: =Assumptions!$C$6*Assumptions!$C$7 -> 168000 | G14: =Assumptions!$C$6*Assumptions!$C$7 -> 168000
B15: Staff | C15: =Assumptions!$C$38 -> 2232000 | D15: =Assumptions!$D$38 -> 2800000 | E15: =Assumptions!$E$38 -> 3200000 | F15: =Assumptions!$F$38 -> 3400000 | G15: =Assumptions!$G$38 -> 3500000
B16: Food & beverage cost of goods | C16: =C10*Assumptions!$C$32 -> 2452800 | D16: =D10*Assumptions!$C$32 -> 4088000 | E16: =E10*Assumptions!$C$32 -> 5723200 | F16: =F10*Assumptions!$C$32 -> 6132000 | G16: =G10*Assumptions!$C$32 -> 6336400
B17: Electricity resale cost (wholesale) | C17: =Assumptions!$C$23*Assumptions!$C$28*Assumptions!$C$24*365*Assumptions!$C$26 -> 1277500 | D17: =Assumptions!$C$23*Assumptions!$D$28*Assumptions!$C$24*365*Assumptions!$C$26 -> 2235625 | E17: =Assumptions!$C$23*Assumptions!$E$28*Assumptions!$C$24*365*Assumptions!$C$26 -> 3193750 | F17: =Assumptions!$C$23*Assumptions!$F$28*Assumptions!$C$24*365*Assumptions!$C$26 -> 3513125 | G17: =Assumptions!$C$23*Assumptions!$G$28*Assumptions!$C$24*365*Assumptions!$C$26 -> 3832500
B18: Utilities | C18: =Assumptions!$C$39 -> 800000 | D18: =Assumptions!$D$39 -> 950000 | E18: =Assumptions!$E$39 -> 1100000 | F18: =Assumptions!$F$39 -> 1150000 | G18: =Assumptions!$G$39 -> 1200000
B19: Marketing | C19: =Assumptions!$C$40 -> 600000 | D19: =Assumptions!$D$40 -> 500000 | E19: =Assumptions!$E$40 -> 500000 | F19: =Assumptions!$F$40 -> 500000 | G19: =Assumptions!$G$40 -> 500000
B20: Admin | C20: =Assumptions!$C$41 -> 400000 | D20: =Assumptions!$D$41 -> 450000 | E20: =Assumptions!$E$41 -> 500000 | F20: =Assumptions!$F$41 -> 520000 | G20: =Assumptions!$G$41 -> 540000
B21: Maintenance | C21: =Assumptions!$C$42 -> 500000 | D21: =Assumptions!$D$42 -> 600000 | E21: =Assumptions!$E$42 -> 700000 | F21: =Assumptions!$F$42 -> 750000 | G21: =Assumptions!$G$42 -> 800000
B22: TOTAL OPERATING COST | C22: =SUM(C14:C21) -> 8430300 | D22: =SUM(D14:D21) -> 11791625 | E22: =SUM(E14:E21) -> 15084950 | F22: =SUM(F14:F21) -> 16133125 | G22: =SUM(G14:G21) -> 16876900
B24: NET INCOME | C24: =C11-C22 -> 8067700 | D24: =D11-D22 -> 14908125 | E24: =E11-E22 -> 20630300 | F24: =F11-F22 -> 22556875 | G24: =G11-G22 -> 23437350

Sheet Cash Flow
B2: Cash Flow
B3: Capex + 5 years of operations + the Year-5 buy/sell transaction
B5: Period | C5: Year 0 (capex) | D5: Year 1 | E5: Year 2 | F5: Year 3 | G5: Year 4 | H5: Year 5
B6: Capital expenditure | C6: =-Capex!C15 -> -38000000 | D6: 0 | E6: 0 | F6: 0 | G6: 0 | H6: 0
B7: Operating net income | C7: 0 | D7: ='Operating P&L'!C24 -> 8067700 | E7: ='Operating P&L'!D24 -> 14908125 | F7: ='Operating P&L'!E24 -> 20630300 | G7: ='Operating P&L'!F24 -> 22556875 | H7: ='Operating P&L'!G24 -> 23437350
B8: Year 5 terminal: sell farm-stay units + buy land | C8: 0 | D8: 0 | E8: 0 | F8: 0 | G8: 0 | H8: =-Assumptions!$C$57+((Assumptions!$C$45*Assumptions!$C$11)*Assumptions!$C$56)+((Assumptions!$C$6*Assumptions!$C$7*5)*Assumptions!$C$58) -> -92600000
B9: = sell farm-stay units (resale value) | H9: =+(Assumptions!$C$45*Assumptions!$C$11)*Assumptions!$C$56 -> 4000000
B10: = rent credited toward purchase | H10: =+(Assumptions!$C$6*Assumptions!$C$7*5)*Assumptions!$C$58 -> 0
B11: = buy the land outright | H11: =-Assumptions!$C$57 -> -96600000
B13: Net cash flow | C13: =C6+C7 -> -38000000 | D13: =D6+D7 -> 8067700 | E13: =E6+E7 -> 14908125 | F13: =F6+F7 -> 20630300 | G13: =G6+G7 -> 22556875 | H13: =H6+H7+H8 -> -69162650
B14: Cumulative cash position | C14: =C13 -> -38000000 | D14: =C14+D13 -> -29932300 | E14: =D14+E13 -> -15024175 | F14: =E14+F13 -> 5606125 | G14: =F14+G13 -> 28163000 | H14: =G14+H13 -> -40999650
B16: The Year-5 column includes the terminal transaction: selling the 20 farm-stay units (est. resale value) plus any rent credited toward the price, minus buying the 42 rai outright. See the breakdown to the right of that row (column H) and the Assumptions sheet for each figure.

Sheet Summary
B2: Farm De Rai — Summary
B3: Live dashboard — change Assumptions and this page updates
B6: KEY NUMBERS
B7: Total land (leased, then purchased at Year 5) | C7: 42 rai
B8: Upfront capital (Capex) | C8: =Capex!C15 -> 38000000
B9: Annual land rent | C9: =Assumptions!$C$6*Assumptions!$C$7 -> 168000
B10: Year 1 net income | C10: ='Operating P&L'!C24 -> 8067700
B11: Year 5 net income (operating) | C11: ='Operating P&L'!G24 -> 23437350
B12: 5-yr cumulative operating profit (before land purchase) | C12: =SUM('Operating P&L'!C24:G24) -> 89600350
B13: Year 5 land purchase price (est.) | C13: =Assumptions!$C$57 -> 96600000
B14: Year 5 farm-stay unit resale (est.) | C14: =Assumptions!$C$45*Assumptions!$C$11*Assumptions!$C$56 -> 4000000
B15: Cumulative cash position after buying the land | C15: ='Cash Flow'!H14 -> -40999650
B16: Rai gifted to the sanctuary after purchase | C16: =Assumptions!$C$59 -> 12
B17: Rai retained for the tourism business | C17: =Assumptions!$C$6-Assumptions!$C$59 -> 30
B19: CASH FLOW
B20: Period | C20: ='Cash Flow'!C5 -> Year 0 (capex) | D20: ='Cash Flow'!D5 -> Year 1 | E20: ='Cash Flow'!E5 -> Year 2 | F20: ='Cash Flow'!F5 -> Year 3 | G20: ='Cash Flow'!G5 -> Year 4 | H20: ='Cash Flow'!H5 -> Year 5
B21: Net cash flow | C21: ='Cash Flow'!C13 -> -38000000 | D21: ='Cash Flow'!D13 -> 8067700 | E21: ='Cash Flow'!E13 -> 14908125 | F21: ='Cash Flow'!F13 -> 20630300 | G21: ='Cash Flow'!G13 -> 22556875 | H21: ='Cash Flow'!H13 -> -69162650
B22: Cumulative cash position | C22: ='Cash Flow'!C14 -> -38000000 | D22: ='Cash Flow'!D14 -> -29932300 | E22: ='Cash Flow'!E14 -> -15024175 | F22: ='Cash Flow'!F14 -> 5606125 | G22: ='Cash Flow'!G14 -> 28163000 | H22: ='Cash Flow'!H14 -> -40999650
B46: This is a planning tool, not a finished bank-ready model. Verify the lease/purchase-option terms with the owner, real construction/procurement quotes, and grid capacity for the fast chargers before relying on this for financing.
