Workbook

Sheet Read Me
B2: Angel Arms Horse Sanctuary — Financial Model
B3: How to use this workbook
B6: This workbook is the live financial model behind the Angel Arms Horse Sanctuary business plan.
B7: Change any blue number and every sheet — including the Summary cash-flow chart — recalculates.
B9: Color legend
B10: Blue text = an input you can change (an assumption or a lever to negotiate with partners)
B11: Black text = a formula (don't overwrite — it's computed from inputs)
B12: Green text = a link pulling a value from another sheet
B13: Pale yellow fill = a key assumption worth double-checking before you rely on this model
B15: Sheet guide
B16: Assumptions — every input driver in one place: land, pricing, horse/visitor volume, costs
B17: Land Schedule — the dated land payment schedule (yours vs. owner-financed pass-through)
... B26: construction quotes, and the partnership contract's exact terms before relying on this for financing.

Sheet Summary
B2: Angel Arms Horse Sanctuary — Summary
B3: Live dashboard — change Assumptions and this page updates
B6: KEY NUMBERS
B7: Total land (10 sanctuary + 32 development) | C7: 42 rai
B8: Your real capital ask (sanctuary) | C8: ='Sanctuary Capex'!C19 -> 54700000
B9: Boarding fee | C9: =Assumptions!$C$24 -> 15000
B10: Sanctuary land (yours) | C10: =Assumptions!$C$6 -> 23000000
B11: 32-rai land (owner-financed, not yours) | C11: =Assumptions!$C$11 -> 73600000
B12: 32-rai infrastructure — charged to plot-sale proceeds (capped) | C12: ='32-rai Economics'!C19 -> -3000000
B13: 32-rai infrastructure — funded by donations | C13: ='32-rai Economics'!C20 -> 10800000
B14: 32-rai profit transferred to Sanctuary (5-yr total) | C14: =SUM('Sanctuary P&L'!C12:G12) -> 9111500
B15: Year 1 combined net | C15: ='Cash Flow'!D8 -> 3758612.5
B16: Year 5 combined net | C16: ='Cash Flow'!H8 -> 5601360
B17: Year 5 cumulative cash position | C17: ='Cash Flow'!H9 -> -28846700
B19: CASH FLOW
B20: Period | C20: ='Cash Flow'!C5 -> Year 0 (capital) | D20: ='Cash Flow'!D5 -> Year 1 | E20: ='Cash Flow'!E5 -> Year 2 | F20: ='Cash Flow'!F5 -> Year 3 | G20: ='Cash Flow'!G5 -> Year 4 | H20: ='Cash Flow'!H5 -> Year 5
B21: Net cash flow | C21: ='Cash Flow'!C8 -> -54700000 | D21: ='Cash Flow'!D8 -> 3758612.5 | E21: ='Cash Flow'!E8 -> 5022583.8 | F21: ='Cash Flow'!F8 -> 6568343.8 | G21: ='Cash Flow'!G8 -> 4902400 | H21: ='Cash Flow'!H8 -> 5601360
B22: Cumulative cash position | C22: ='Cash Flow'!C9 -> -54700000 | D22: ='Cash Flow'!D9 -> -50941388 | E22: ='Cash Flow'!E9 -> -45918804 | F22: ='Cash Flow'!F9 -> -39350460 | G22: ='Cash Flow'!G9 -> -34448060 | H22: ='Cash Flow'!H9 -> -28846700
B46: This document is a planning tool. All figures are planning-level estimates from the business-plan discussion —
B47: verify land prices, construction quotes, and the partnership contract's exact terms before committing capital.

Sheet Assumptions
B2: Assumptions
B3: Every input the model uses — change values here (blue cells)
B5: LAND
B6: Sanctuary land total (10 rai) | C6: 23000000
B7: Sanctuary land deposit | C7: 6000000
B8: Sanctuary land balance (formula) | C8: =C6-C7 -> 17000000
B9: Sanctuary deposit date | C9: 46296
B10: Sanctuary balance date | C10: 46478
B11: 32-rai land total (owner-financed) | C11: 73600000
B12: 32-rai installment count | C12: 6
B13: 32-rai installment amount (formula) | C13: =C11/C12 -> 12266667
B14: 32-rai first installment date | C14: 46569
B15: 32-rai installment interval (months) | C15: 3
B17: SANCTUARY — HORSE & VISITOR VOLUME
B18: Assumption | C18: Year 1 | D18: Year 2 | E18: Year 3 | F18: Year 4 | G18: Year 5 | H18: Notes
B19: Horses in residence | C19: 15 | D19: 22 | E19: 28 | F19: 32 | G19: 35
B20: Visitors (tours, per year) | C20: 2000 | D20: 3500 | E20: 4500 | F20: 5500 | G20: 6000
B21: Children in therapy program (info only) | C21: 120 | D21: 220 | E21: 340 | F21: 420 | G21: 500
B23: SANCTUARY — PRICING
B24: Boarding fee (THB / horse / month) | C24: 15000
B25: Admission price (THB / visitor) | C25: 300
B26: Lesson uptake (% of visitors) | C26: 0.2
B27: Lesson price (THB / session) | C27: 700
B28: Feed / routine care cost (THB / horse / month) | C28: 4500 | H28: Vet fees are billed directly to the owner — not in this model
B30: SANCTUARY — DONATIONS, GRANTS, STAFF & OPEX (per year)
B31: Assumption | C31: Year 1 | D31: Year 2 | E31: Year 3 | F31: Year 4 | G31: Year 5 | H31: Notes
B32: Donations (general) | C32: 1200000 | D32: 1400000 | E32: 1600000 | F32: 1800000 | G32: 2000000
B33: Therapy program CSR / grants | C33: 800000 | D33: 1200000 | E33: 1700000 | F33: 2100000 | G33: 2500000
B34: Sanctuary staff cost | C34: 3200000 | D34: 3600000 | E34: 4000000 | F34: 4300000 | G34: 4600000
B35: Therapy program staff / equipment | C35: 600000 | D35: 900000 | E35: 1200000 | F35: 1400000 | G35: 1600000
B36: Utilities / maintenance | C36: 350000 | D36: 400000 | E36: 450000 | F36: 480000 | G36: 500000
B37: Admin / overhead | C37: 300000 | D37: 320000 | E37: 340000 | F37: 360000 | G37: 380000
B39: COMMUNITY — UNITS, RATES & OCCUPANCY
B40: Glamping units (count) | C40: 3
B41: Glamping nightly rate (THB) | C41: 2500
B42: Assumption | C42: Year 1 | D42: Year 2 | E42: Year 3 | F42: Year 4 | G42: Year 5 | H42: Notes
B43: Glamping occupancy % | C43: 0.15 | D43: 0.25 | E43: 0.35 | F43: 0.4 | G43: 0.42
B44: EV sites (count) | C44: 4
B45: EV nightly rate (THB) | C45: 800
B46: Assumption | C46: Year 1 | D46: Year 2 | E46: Year 3 | F46: Year 4 | G46: Year 5 | H46: Notes
...

Sheet Land Schedule
B2: Land Payment Schedule
B3: Total ฿ 96.6M — only the sanctuary line (~฿ 23M) is your own capital
B5: Date | C5: Payment | D5: Amount (THB) | E5: Who funds it
B6: =Assumptions!$C$9 -> 46296 | C6: Sanctuary land deposit (10 rai) | D6: =Assumptions!$C$7 -> 6000000 | E6: You
B7: =Assumptions!$C$10 -> 46478 | C7: Sanctuary land balance (10 rai) | D7: =Assumptions!$C$8 -> 17000000 | E7: You
B8: =EDATE(Assumptions!$C$14,0*Assumptions!$C$15) -> 46569 | C8: 32-rai installment 1/6 | D8: =Assumptions!$C$13 -> 12266667 | E8: Pass-through
B9: =EDATE(Assumptions!$C$14,1*Assumptions!$C$15) -> 46661 | C9: 32-rai installment 2/6 | D9: =Assumptions!$C$13 -> 12266667 | E9: Pass-through
B10: =EDATE(Assumptions!$C$14,2*Assumptions!$C$15) -> 46753 | C10: 32-rai installment 3/6 | D10: =Assumptions!$C$13 -> 12266667 | E10: Pass-through
B11: =EDATE(Assumptions!$C$14,3*Assumptions!$C$15) -> 46844 | C11: 32-rai installment 4/6 | D11: =Assumptions!$C$13 -> 12266667 | E11: Pass-through
B12: =EDATE(Assumptions!$C$14,4*Assumptions!$C$15) -> 46935 | C12: 32-rai installment 5/6 | D12: =Assumptions!$C$13 -> 12266667 | E12: Pass-through
B13: =EDATE(Assumptions!$C$14,5*Assumptions!$C$15) -> 47027 | C13: 32-rai installment 6/6 | D13: =Assumptions!$C$13 -> 12266667 | E13: Pass-through
C15: TOTAL (all payments) | D15: =SUM(D6:D13) -> 96600000
C16: of which YOURS | D16: =SUMIF(E6:E13,"You",D6:D13) -> 23000000
C17: of which PASS-THROUGH (owner-financed) | D17: =SUMIF(E6:E13,"Pass-through",D6:D13) -> 73600000
B19: The 32-rai schedule is a pass-through: the owner transfers each plot's deed once buyer payments satisfy that milestone. Get shortfall terms in writing.

Sheet Sanctuary Capex
B2: Sanctuary Capital Requirement (10 rai)
B3: The real capital ask — land + construction/fit-out
B5: Item | C5: Amount (THB) | D5: % of total
B6: Land (10 rai) | C6: =Assumptions!$C$6 -> 23000000 | D6: =C6/$C$19 -> 0.42047532
B7: Main stable barn (22 stalls) | C7: =Assumptions!$C$80 -> 13000000 | D7: =C7/$C$19 -> 0.23765996
B8: Covered riding / therapy arena | C8: =Assumptions!$C$81 -> 4500000 | D8: =C8/$C$19 -> 0.08226691
B9: Quarantine & veterinary clinic (building) | C9: =Assumptions!$C$82 -> 2900000 | D9: =C9/$C$19 -> 0.053016453
B10: Site prep & infrastructure | C10: =Assumptions!$C$83 -> 2500000 | D10: =C10/$C$19 -> 0.045703839
B11: Admin / reception / therapy office | C11: =Assumptions!$C$84 -> 1800000 | D11: =C11/$C$19 -> 0.032906764
B12: Equipment & vehicles | C12: =Assumptions!$C$85 -> 1500000 | D12: =C12/$C$19 -> 0.027422303
B13: Perimeter & paddock fencing | C13: =Assumptions!$C$86 -> 1500000 | D13: =C13/$C$19 -> 0.027422303
B14: Contingency + legal | C14: =Assumptions!$C$87 -> 1200000 | D14: =C14/$C$19 -> 0.021937843
B15: Multi-terrain pasture establishment | C15: =Assumptions!$C$88 -> 900000 | D15: =C15/$C$19 -> 0.016453382
B16: Working capital reserve | C16: =Assumptions!$C$89 -> 800000 | D16: =C16/$C$19 -> 0.014625229
B17: Staff housing | C17: =Assumptions!$C$90 -> 600000 | D17: =C17/$C$19 -> 0.010968921
B18: Initial stable fit-out & onboarding | C18: =Assumptions!$C$91 -> 500000 | D18: =C18/$C$19 -> 0.0091407678
B19: TOTAL SANCTUARY CAPITAL | C19: =SUM(C6:C18) -> 54700000 | D19: 1
B21: of which is land | C21: =C6 -> 23000000
B22: of which is construction / fit-out | C22: =C19-C6 -> 31700000

Sheet 32-rai Economics
B2: 32-rai Development Economics
B3: Owner-financed land — your exposure is the infrastructure spend
B5: Line item | C5: Amount (THB) | D5: Who bears it
B6: Sellable rai (32 - communal) | C6: =Assumptions!$C$65 -> 27
B7: Sale revenue (sellable rai × price/rai) | C7: =C6*Assumptions!$C$66 -> 94500000 | D7: You collect from buyers
B8: Owner's land share (pass-through) | C8: =-Assumptions!$C$11 -> -73600000 | D8: Pass-through, not your cost
B9: YOUR GROSS MARGIN | C9: =C7+C8 -> 20900000
B11: Internal estate roads | C11: =-Assumptions!$C$67 -> -3500000 | D11: Your capital
B12: Utilities extension to plots | C12: =-Assumptions!$C$68 -> -2000000 | D12: Your capital
B13: Communal clubhouse / café | C13: =-Assumptions!$C$69 -> -3500000 | D13: Your capital
B14: Shared glamping capex | C14: =-Assumptions!$C$70 -> -2000000 | D14: Your capital
B15: Shared EV camping capex | C15: =-Assumptions!$C$71 -> -500000 | D15: Your capital
B16: Flood-proof floating villa capex | C16: =-Assumptions!$C$72 -> -1500000 | D16: Your capital
B17: Subdivision survey / title-splitting | C17: =-Assumptions!$C$73 -> -800000 | D17: Your capital
B18: Subtotal infrastructure (full cost) | C18: =SUM(C11:C17) -> -13800000
B19: of which charged to plot-sale proceeds (capped) | C19: =MAX(C18,-Assumptions!$C$77) -> -3000000
B20: of which funded by donations (external) | C20: =-(C18-C19) -> 10800000
B22: Agent fee (on sale) | C22: =-C7*Assumptions!$C$74 -> -4725000 | D22: Deducted from proceeds
B23: Transfer fee + Specific Business Tax (est.) | C23: =-C7*(Assumptions!$C$75+Assumptions!$C$76) -> -4063500 | D23: Deducted from proceeds
B25: NET MARGIN (after agent fee) | C25: =C9+C19+C22+C23 -> 9111500
B26: → transferred to the Sanctuary as revenue (see Sanctuary P&L) | C26: =IF(C25>0,C25,"฿0 — no profit to transfer at this fee/cost rate") -> 9111500
B28: Infrastructure cost above the cap is assumed donation-funded rather than deducted from plot-sale proceeds — confirm that donor commitment is real before relying on this margin. Your capital exposure here is just the capped amount, ideally funded from buyer deposits.

Sheet Sanctuary P&L
B2: Sanctuary 5-Year Operating Plan
B3: Retirement boarding + therapy — a real paying business
B5: Assumption | C5: Year 1 | D5: Year 2 | E5: Year 3 | F5: Year 4 | G5: Year 5 | H5: Notes
B6: REVENUE
B7: Boarding fees (horses × ฿ /mo × 12) | C7: =Assumptions!$C$19*Assumptions!$C$24*12 -> 2700000 | D7: =Assumptions!$D$19*Assumptions!$C$24*12 -> 3960000 | E7: =Assumptions!$E$19*Assumptions!$C$24*12 -> 5040000 | F7: =Assumptions!$F$19*Assumptions!$C$24*12 -> 5760000 | G7: =Assumptions!$G$19*Assumptions!$C$24*12 -> 6300000
B8: Admissions / tours | C8: =Assumptions!$C$20*Assumptions!$C$25 -> 600000 | D8: =Assumptions!$D$20*Assumptions!$C$25 -> 1050000 | E8: =Assumptions!$E$20*Assumptions!$C$25 -> 1350000 | F8: =Assumptions!$F$20*Assumptions!$C$25 -> 1650000 | G8: =Assumptions!$G$20*Assumptions!$C$25 -> 1800000
B9: Riding lessons | C9: =Assumptions!$C$20*Assumptions!$C$26*Assumptions!$C$27 -> 280000 | D9: =Assumptions!$D$20*Assumptions!$C$26*Assumptions!$C$27 -> 490000 | E9: =Assumptions!$E$20*Assumptions!$C$26*Assumptions!$C$27 -> 630000 | F9: =Assumptions!$F$20*Assumptions!$C$26*Assumptions!$C$27 -> 770000 | G9: =Assumptions!$G$20*Assumptions!$C$26*Assumptions!$C$27 -> 840000
B10: Donations (general) | C10: =Assumptions!$C$32 -> 1200000 | D10: =Assumptions!$D$32 -> 1400000 | E10: =Assumptions!$E$32 -> 1600000 | F10: =Assumptions!$F$32 -> 1800000 | G10: =Assumptions!$G$32 -> 2000000
B11: Therapy program CSR / grants | C11: =Assumptions!$C$33 -> 800000 | D11: =Assumptions!$D$33 -> 1200000 | E11: =Assumptions!$E$33 -> 1700000 | F11: =Assumptions!$F$33 -> 2100000 | G11: =Assumptions!$G$33 -> 2500000
B12: 32-rai development profit share (net of agent fee) | C12: =MAX(IFERROR('32-rai Economics'!$C$25*((Assumptions!$C$55)-(0))/Assumptions!$G$55,0),0) -> 3416812.5 | D12: =MAX(IFERROR('32-rai Economics'!$C$25*((Assumptions!$D$55)-(Assumptions!$C$55))/Assumptions!$G$55,0),0) -> 2847343.8 | E12: =MAX(IFERROR('32-rai Economics'!$C$25*((Assumptions!$E$55)-(Assumptions!$D$55))/Assumptions!$G$55,0),0) -> 2847343.8 | F12: =MAX(IFERROR('32-rai Economics'!$C$25*((Assumptions!$F$55)-(Assumptions!$E$55))/Assumptions!$G$55,0),0) -> 0 | G12: =MAX(IFERROR('32-rai Economics'!$C$25*((Assumptions!$G$55)-(Assumptions!$F$55))/Assumptions!$G$55,0),0) -> 0 | H12: Net margin from '32-rai Economics', prorated by plots sold that year — floored at ฿0 if the development runs a loss
B13: TOTAL REVENUE | C13: =SUM(C7:C12) -> 8996812.5 | D13: =SUM(D7:D12) -> 10947344 | E13: =SUM(E7:E12) -> 13167344 | F13: =SUM(F7:F12) -> 12080000 | G13: =SUM(G7:G12) -> 13440000
B15: OPERATING COST
B16: Sanctuary staff | C16: =Assumptions!$C$34 -> 3200000 | D16: =Assumptions!$D$34 -> 3600000 | E16: =Assumptions!$E$34 -> 4000000 | F16: =Assumptions!$F$34 -> 4300000 | G16: =Assumptions!$G$34 -> 4600000
B17: Therapy program staff / equipment | C17: =Assumptions!$C$35 -> 600000 | D17: =Assumptions!$D$35 -> 900000 | E17: =Assumptions!$E$35 -> 1200000 | F17: =Assumptions!$F$35 -> 1400000 | G17: =Assumptions!$G$35 -> 1600000
B18: Feed / routine care (horses × ฿ /mo × 12) | C18: =Assumptions!$C$19*Assumptions!$C$28*12 -> 810000 | D18: =Assumptions!$D$19*Assumptions!$C$28*12 -> 1188000 | E18: =Assumptions!$E$19*Assumptions!$C$28*12 -> 1512000 | F18: =Assumptions!$F$19*Assumptions!$C$28*12 -> 1728000 | G18: =Assumptions!$G$19*Assumptions!$C$28*12 -> 1890000
B19: Utilities / maintenance | C19: =Assumptions!$C$36 -> 350000 | D19: =Assumptions!$D$36 -> 400000 | E19: =Assumptions!$E$36 -> 450000 | F19: =Assumptions!$F$36 -> 480000 | G19: =Assumptions!$G$36 -> 500000
B20: Admin / overhead | C20: =Assumptions!$C$37 -> 300000 | D20: =Assumptions!$D$37 -> 320000 | E20: =Assumptions!$E$37 -> 340000 | F20: =Assumptions!$F$37 -> 360000 | G20: =Assumptions!$G$37 -> 380000
B21: TOTAL OPERATING COST | C21: =SUM(C16:C20) -> 5260000 | D21: =SUM(D16:D20) -> 6408000 | E21: =SUM(E16:E20) -> 7502000 | F21: =SUM(F16:F20) -> 8268000 | G21: =SUM(G16:G20) -> 8970000
B23: SANCTUARY NET | C23: =C13-C21 -> 3736812.5 | D23: =D13-D21 -> 4539343.8 | E23: =E13-E21 -> 5665343.8 | F23: =F13-F21 -> 3812000 | G23: =G13-G21 -> 4470000
B25: Vet fees are billed and paid directly by the horse owner — not included here as Foundation revenue or cost.

Sheet Community P&L
B2: Community Amenities 5-Year Operating Plan
B3: Café, glamping, EV camping, floating villa, HOA fees
B5: Assumption | C5: Year 1 | D5: Year 2 | E5: Year 3 | F5: Year 4 | G5: Year 5 | H5: Notes
B6: REVENUE
B7: Shared glamping (units × occ × rate × 365) | C7: =Assumptions!$C$40*Assumptions!$C$43*Assumptions!$C$41*365 -> 410625 | D7: =Assumptions!$C$40*Assumptions!$D$43*Assumptions!$C$41*365 -> 684375 | E7: =Assumptions!$C$40*Assumptions!$E$43*Assumptions!$C$41*365 -> 958125 | F7: =Assumptions!$C$40*Assumptions!$F$43*Assumptions!$C$41*365 -> 1095000 | G7: =Assumptions!$C$40*Assumptions!$G$43*Assumptions!$C$41*365 -> 1149750
B8: Shared EV camping (sites × occ × rate × 365) | C8: =Assumptions!$C$44*Assumptions!$C$47*Assumptions!$C$45*365 -> 116800 | D8: =Assumptions!$C$44*Assumptions!$D$47*Assumptions!$C$45*365 -> 210240 | E8: =Assumptions!$C$44*Assumptions!$E$47*Assumptions!$C$45*365 -> 292000 | F8: =Assumptions!$C$44*Assumptions!$F$47*Assumptions!$C$45*365 -> 350400 | G8: =Assumptions!$C$44*Assumptions!$G$47*Assumptions!$C$45*365 -> 373760
B9: Floating villa (units × occ × rate × 365) | C9: =Assumptions!$C$48*Assumptions!$C$51*Assumptions!$C$49*365 -> 246375 | D9: =Assumptions!$C$48*Assumptions!$D$51*Assumptions!$C$49*365 -> 410625 | E9: =Assumptions!$C$48*Assumptions!$E$51*Assumptions!$C$49*365 -> 574875 | F9: =Assumptions!$C$48*Assumptions!$F$51*Assumptions!$C$49*365 -> 657000 | G9: =Assumptions!$C$48*Assumptions!$G$51*Assumptions!$C$49*365 -> 689850
B10: Café (visitors × spend + plots × spend) | C10: =Assumptions!$C$20*Assumptions!$C$56+Assumptions!$C$55*Assumptions!$C$57 -> 168000 | D10: =Assumptions!$D$20*Assumptions!$C$56+Assumptions!$D$55*Assumptions!$C$57 -> 298000 | E10: =Assumptions!$E$20*Assumptions!$C$56+Assumptions!$E$55*Assumptions!$C$57 -> 398000 | F10: =Assumptions!$F$20*Assumptions!$C$56+Assumptions!$F$55*Assumptions!$C$57 -> 458000 | G10: =Assumptions!$G$20*Assumptions!$C$56+Assumptions!$G$55*Assumptions!$C$57 -> 488000
B11: HOA / common-area fee (plots sold × fee) | C11: =Assumptions!$C$55*Assumptions!$C$58 -> 180000 | D11: =Assumptions!$D$55*Assumptions!$C$58 -> 330000 | E11: =Assumptions!$E$55*Assumptions!$C$58 -> 480000 | F11: =Assumptions!$F$55*Assumptions!$C$58 -> 480000 | G11: =Assumptions!$G$55*Assumptions!$C$58 -> 480000
B12: TOTAL REVENUE | C12: =SUM(C7:C11) -> 1121800 | D12: =SUM(D7:D11) -> 1933240 | E12: =SUM(E7:E11) -> 2703000 | F12: =SUM(F7:F11) -> 3040400 | G12: =SUM(G7:G11) -> 3181360
B14: OPERATING COST
B15: Community staff / hospitality | C15: =Assumptions!$C$59 -> 900000 | D15: =Assumptions!$D$59 -> 1100000 | E15: =Assumptions!$E$59 -> 1300000 | F15: =Assumptions!$F$59 -> 1400000 | G15: =Assumptions!$G$59 -> 1450000
B16: Community upkeep | C16: =Assumptions!$C$60 -> 200000 | D16: =Assumptions!$D$60 -> 350000 | E16: =Assumptions!$E$60 -> 500000 | F16: =Assumptions!$F$60 -> 550000 | G16: =Assumptions!$G$60 -> 600000
B17: TOTAL OPERATING COST | C17: =SUM(C15:C16) -> 1100000 | D17: =SUM(D15:D16) -> 1450000 | E17: =SUM(E15:E16) -> 1800000 | F17: =SUM(F15:F16) -> 1950000 | G17: =SUM(G15:G16) -> 2050000
B19: COMMUNITY NET | C19: =C12-C17 -> 21800 | D19: =D12-D17 -> 483240 | E19: =E12-E17 -> 903000 | F19: =F12-F17 -> 1090400 | G19: =G12-G17 -> 1131360

Sheet Cash Flow
B2: Combined Cash Flow
B3: Capital (Year 0) + 5-year operating cash flow — your money only
B5: Period | C5: Year 0 (capital) | D5: Year 1 | E5: Year 2 | F5: Year 3 | G5: Year 4 | H5: Year 5
B6: Capital spend (sanctuary land + construction) | C6: =-'Sanctuary Capex'!C19 -> -54700000 | D6: 0 | E6: 0 | F6: 0 | G6: 0 | H6: 0
B7: Operating net (sanctuary + community) | C7: 0 | D7: ='Sanctuary P&L'!C23+'Community P&L'!C19 -> 3758612.5 | E7: ='Sanctuary P&L'!D23+'Community P&L'!D19 -> 5022583.8 | F7: ='Sanctuary P&L'!E23+'Community P&L'!E19 -> 6568343.8 | G7: ='Sanctuary P&L'!F23+'Community P&L'!F19 -> 4902400 | H7: ='Sanctuary P&L'!G23+'Community P&L'!G19 -> 5601360
B8: Net cash flow | C8: =C6+C7 -> -54700000 | D8: =D6+D7 -> 3758612.5 | E8: =E6+E7 -> 5022583.8 | F8: =F6+F7 -> 6568343.8 | G8: =G6+G7 -> 4902400 | H8: =H6+H7 -> 5601360
B9: Cumulative cash position | C9: =C8 -> -54700000 | D9: =C9+D8 -> -50941388 | E9: =D9+E8 -> -45918804 | F9: =E9+F8 -> -39350460 | G9: =F9+G8 -> -34448060 | H9: =G9+H8 -> -28846700
B12: Note: the 32-rai land (฿ 73.6M) is owner-financed against plot-sale proceeds and is deliberately excluded from
B13: this cash flow — see the Land Schedule sheet for the full dated schedule including that pass-through portion.
